{
  Throwable caught=null;
  try {
    r.call();
  }
 catch (  Throwable t) {
    if (expected != t.getClass())     throw new AssertionError("Expected exception " + expected + ", got "+ t,t);
    caught=t;
  }
  if (expected != null && caught == null)   Assert.fail("Expected exception " + expected + " but call completed successfully.");
}
